#excepciones

numberOne = 5
numberTwo = 1
numberTwo = "1"

# Excepción base: try except

try:
    print(numberOne + numberTwo)
    print("No se ha producido un error")
except:
    # Se ejecuta si se produce una excepción
    print("Se ha producido un error")
